Workbook

Sheet README
A1: Phase 0 + Phase 1 Workbook — Timetable Feasibility Screen
A3: PURPOSE
A4: Takes a raw student roster and teacher list, and answers one question before any
A5: solver runs: how many parallel columns does this grade need, and is it staffable?
A6: Everything recalculates from the Roster sheet, so a new school's data can be pasted
A7: in and the bounds update automatically.
A9: HOW TO USE FOR A NEW SCHOOL
A10: 1. Config!B2 — set the grade to analyse (one grade at a time).
A11: 2. Config!B3 — set the class-size cap.
A12: 3. Roster — paste Id, Grade, and each student's subjects in S1..S10.
A13: 4. Subjects!F — enter each subject's qualification pool size (how many staff COULD teach it).
A14: 5. Read Bounds. If it says INFEASIBLE, the reason is named — fix that before solving.
... A31: "proven feasible". Phase 3 (CP-SAT) is still the arbiter.

Sheet Config
A1: Config
A2: Grade to analyse | B2: 12 | C2: Must match a value in Roster column B.
A3: Class-size cap | B3: 25 | C3: Max students per section. Drives the section floor.
A5: Universal-block subjects | B5: EN, LO, PE, MA, ML | C5: Taken by (almost) every student; consume columns but create no basket diversity.
A6: Choice subjects | B6: 16 | C6: AC, AF, BS, CAT, DA, DR, ED, FR, GE, HI, IT, LS, MU, SC, VA, ZU

Sheet Roster
A1: Id | B1: Grade | C1: In scope | D1: S1 | E1: S2 | F1: S3 | G1: S4 | H1: S5 | I1: S6 | J1: S7 | K1: S8 | L1: S9
A2: 1 | B2: 12 | C2: =IF($B2=Config!$B$2,1,0) -> 1 | D2: EN | E2: LO | F2: PE | G2: MA | H2: AF | I2: CAT | J2: IT | K2: SC
A3: 2 | B3: 12 | C3: =IF($B3=Config!$B$2,1,0) -> 1 | D3: EN | E3: LO | F3: PE | G3: ML | H3: ZU | I3: BS | J3: DA | K3: DR
A4: 3 | B4: 12 | C4: =IF($B4=Config!$B$2,1,0) -> 1 | D4: EN | E4: LO | F4: PE | G4: ML | H4: AF | I4: DR | J4: HI | K4: VA
A5: 4 | B5: 12 | C5: =IF($B5=Config!$B$2,1,0) -> 1 | D5: EN | E5: LO | F5: PE | G5: MA | H5: AF | I5: ED | J5: LS | K5: SC
A6: 5 | B6: 12 | C6: =IF($B6=Config!$B$2,1,0) -> 1 | D6: EN | E6: LO | F6: PE | G6: MA | H6: AF | I6: DA | J6: LS | K6: SC
A7: 6 | B7: 12 | C7: =IF($B7=Config!$B$2,1,0) -> 1 | D7: EN | E7: LO | F7: PE | G7: MA | H7: AF | I7: AC | J7: DR | K7: LS | L7: SC
A8: 7 | B8: 12 | C8: =IF($B8=Config!$B$2,1,0) -> 1 | D8: EN | E8: LO | F8: PE | G8: MA | H8: AF | I8: DR | J8: LS | K8: SC
A9: 8 | B9: 12 | C9: =IF($B9=Config!$B$2,1,0) -> 1 | D9: EN | E9: LO | F9: PE | G9: MA | H9: AF | I9: CAT | J9: LS | K9: SC
A10: 9 | B10: 12 | C10: =IF($B10=Config!$B$2,1,0) -> 1 | D10: EN | E10: LO | F10: PE | G10: ML | H10: AF | I10: BS | J10: HI | K10: LS
A11: 10 | B11: 12 | C11: =IF($B11=Config!$B$2,1,0) -> 1 | D11: EN | E11: LO | F11: PE | G11: MA | H11: AF | I11: LS | J11: SC | K11: VA
A12: 11 | B12: 12 | C12: =IF($B12=Config!$B$2,1,0) -> 1 | D12: EN | E12: LO | F12: PE | G12: ML | H12: AF | I12: BS | J12: DR | K12: ED
A13: 12 | B13: 12 | C13: =IF($B13=Config!$B$2,1,0) -> 1 | D13: EN | E13: LO | F13: PE | G13: MA | H13: AF | I13: ED | J13: MU | K13: SC
A14: 13 | B14: 12 | C14: =IF($B14=Config!$B$2,1,0) -> 1 | D14: EN | E14: LO | F14: PE | G14: MA | H14: AF | I14: DR | J14: IT | K14: VA
A15: 14 | B15: 12 | C15: =IF($B15=Config!$B$2,1,0) -> 1 | D15: EN | E15: LO | F15: PE | G15: MA | H15: AF | I15: AC | J15: BS | K15: HI | L15: SC
A16: 15 | B16: 12 | C16: =IF($B16=Config!$B$2,1,0) -> 1 | D16: EN | E16: LO | F16: PE | G16: MA | H16: AF | I16: BS | J16: HI | K16: SC
A17: 16 | B17: 12 | C17: =IF($B17=Config!$B$2,1,0) -> 1 | D17: EN | E17: LO | F17: PE | G17: ML | H17: ZU | I17: BS | J17: GE | K17: LS
A18: 17 | B18: 12 | C18: =IF($B18=Config!$B$2,1,0) -> 1 | D18: EN | E18: LO | F18: PE | G18: MA | H18: AF | I18: AC | J18: BS | K18: SC
A19: 18 | B19: 12 | C19: =IF($B19=Config!$B$2,1,0) -> 1 | D19: EN | E19: LO | F19: PE | G19: ML | H19: AF | I19: BS | J19: DA | K19: LS
A20: 19 | B20: 12 | C20: =IF($B20=Config!$B$2,1,0) -> 1 | D20: EN | E20: LO | F20: PE | G20: ML | H20: AF | I20: CAT | J20: GE | K20: VA
A21: 20 | B21: 12 | C21: =IF($B21=Config!$B$2,1,0) -> 1 | D21: EN | E21: LO | F21: PE | G21: ML | H21: AF | I21: BS | J21: DA | K21: GE
A22: 21 | B22: 12 | C22: =IF($B22=Config!$B$2,1,0) -> 1 | D22: EN | E22: LO | F22: PE | G22: ML | H22: ZU | I22: BS | J22: DA | K22: HI
A23: 22 | B23: 12 | C23: =IF($B23=Config!$B$2,1,0) -> 1 | D23: EN | E23: LO | F23: PE | G23: MA | H23: AF | I23: BS | J23: CAT | K23: ED | L23: SC
A24: 23 | B24: 12 | C24: =IF($B24=Config!$B$2,1,0) -> 1 | D24: EN | E24: LO | F24: PE | G24: MA | H24: AF | I24: DR | J24: IT | K24: SC
A25: 24 | B25: 12 | C25: =IF($B25=Config!$B$2,1,0) -> 1 | D25: EN | E25: LO | F25: PE | G25: MA | H25: ZU | I25: LS | J25: SC | K25: VA
A26: 25 | B26: 12 | C26: =IF($B26=Config!$B$2,1,0) -> 1 | D26: EN | E26: LO | F26: PE | G26: MA | H26: AF | I26: IT | J26: LS | K26: SC
A27: 26 | B27: 12 | C27: =IF($B27=Config!$B$2,1,0) -> 1 | D27: EN | E27: LO | F27: PE | G27: MA | H27: AF | I27: GE | J27: LS | K27: SC
A28: 27 | B28: 12 | C28: =IF($B28=Config!$B$2,1,0) -> 1 | D28: EN | E28: LO | F28: PE | G28: ML | H28: ZU | I28: BS | J28: DR | K28: LS
A29: 28 | B29: 12 | C29: =IF($B29=Config!$B$2,1,0) -> 1 | D29: EN | E29: LO | F29: PE | G29: MA | H29: AF | I29: BS | J29: CAT | K29: SC
A30: 29 | B30: 12 | C30: =IF($B30=Config!$B$2,1,0) -> 1 | D30: EN | E30: LO | F30: PE | G30: MA | H30: AF | I30: AC | J30: LS | K30: SC
A31: 30 | B31: 12 | C31: =IF($B31=Config!$B$2,1,0) -> 1 | D31: EN | E31: LO | F31: PE | G31: ML | H31: AF | I31: BS | J31: DR | K31: HI
A32: 31 | B32: 12 | C32: =IF($B32=Config!$B$2,1,0) -> 1 | D32: EN | E32: LO | F32: PE | G32: ML | H32: AF | I32: BS | J32: HI | K32: VA
A33: 32 | B33: 12 | C33: =IF($B33=Config!$B$2,1,0) -> 1 | D33: EN | E33: LO | F33: PE | G33: ML | H33: AF | I33: BS | J33: GE | K33: HI
A34: 33 | B34: 12 | C34: =IF($B34=Config!$B$2,1,0) -> 1 | D34: EN | E34: LO | F34: PE | G34: MA | H34: AF | I34: AC | J34: BS | K34: SC
A35: 34 | B35: 12 | C35: =IF($B35=Config!$B$2,1,0) -> 1 | D35: EN | E35: LO | F35: PE | G35: MA | H35: BS | I35: GE | J35: LS | K35: SC
A36: 35 | B36: 12 | C36: =IF($B36=Config!$B$2,1,0) -> 1 | D36: EN | E36: LO | F36: PE | G36: MA | H36: AF | I36: ED | J36: IT | K36: SC | L36: VA
A37: 36 | B37: 12 | C37: =IF($B37=Config!$B$2,1,0) -> 1 | D37: EN | E37: LO | F37: PE | G37: ML | H37: AF | I37: BS | J37: HI | K37: LS
A38: 37 | B38: 12 | C38: =IF($B38=Config!$B$2,1,0) -> 1 | D38: EN | E38: LO | F38: PE | G38: ML | H38: AF | I38: AC | J38: BS | K38: VA
A39: 38 | B39: 12 | C39: =IF($B39=Config!$B$2,1,0) -> 1 | D39: EN | E39: LO | F39: PE | G39: MA | H39: AF | I39: ED | J39: LS | K39: SC
A40: 39 | B40: 12 | C40: =IF($B40=Config!$B$2,1,0) -> 1 | D40: EN | E40: LO | F40: PE | G40: MA | H40: AF | I40: ED | J40: IT | K40: SC
...

Sheet Matrix
A1: Id | B1: In | C1: EN | D1: LO | E1: PE | F1: MA | G1: ML | H1: AC | I1: AF | J1: BS | K1: CAT | L1: DA | M1: DR | N1: ED | O1: FR | P1: GE | Q1: HI | R1: IT | S1: LS | T1: MU | U1: SC | V1: VA | W1: ZU | X1: Basket
A2: =Roster!A2 -> 1 | B2: =Roster!C2 -> 1 | C2: =IF(COUNTIF(Roster!$D2:$M2,C$1)>0,$B2,0) -> 1 | D2: =IF(COUNTIF(Roster!$D2:$M2,D$1)>0,$B2,0) -> 1 | E2: =IF(COUNTIF(Roster!$D2:$M2,E$1)>0,$B2,0) -> 1 | F2: =IF(COUNTIF(Roster!$D2:$M2,F$1)>0,$B2,0) -> 1 | G2: =IF(COUNTIF(Roster!$D2:$M2,G$1)>0,$B2,0) -> 0 | H2: =IF(COUNTIF(Roster!$D2:$M2,H$1)>0,$B2,0) -> 0 | I2: =IF(COUNTIF(Roster!$D2:$M2,I$1)>0,$B2,0) -> 1 | J2: =IF(COUNTIF(Roster!$D2:$M2,J$1)>0,$B2,0) -> 0 | ... W2: =IF(COUNTIF(Roster!$D2:$M2,W$1)>0,$B2,0) -> 0 | X2: =SUM(H2:W2) -> 4
A3: =Roster!A3 -> 2 | B3: =Roster!C3 -> 1 | C3: =IF(COUNTIF(Roster!$D3:$M3,C$1)>0,$B3,0) -> 1 | D3: =IF(COUNTIF(Roster!$D3:$M3,D$1)>0,$B3,0) -> 1 | E3: =IF(COUNTIF(Roster!$D3:$M3,E$1)>0,$B3,0) -> 1 | F3: =IF(COUNTIF(Roster!$D3:$M3,F$1)>0,$B3,0) -> 0 | G3: =IF(COUNTIF(Roster!$D3:$M3,G$1)>0,$B3,0) -> 1 | H3: =IF(COUNTIF(Roster!$D3:$M3,H$1)>0,$B3,0) -> 0 | I3: =IF(COUNTIF(Roster!$D3:$M3,I$1)>0,$B3,0) -> 0 | J3: =IF(COUNTIF(Roster!$D3:$M3,J$1)>0,$B3,0) -> 1 | ... W3: =IF(COUNTIF(Roster!$D3:$M3,W$1)>0,$B3,0) -> 1 | X3: =SUM(H3:W3) -> 4
A4: =Roster!A4 -> 3 | B4: =Roster!C4 -> 1 | C4: =IF(COUNTIF(Roster!$D4:$M4,C$1)>0,$B4,0) -> 1 | D4: =IF(COUNTIF(Roster!$D4:$M4,D$1)>0,$B4,0) -> 1 | E4: =IF(COUNTIF(Roster!$D4:$M4,E$1)>0,$B4,0) -> 1 | F4: =IF(COUNTIF(Roster!$D4:$M4,F$1)>0,$B4,0) -> 0 | G4: =IF(COUNTIF(Roster!$D4:$M4,G$1)>0,$B4,0) -> 1 | H4: =IF(COUNTIF(Roster!$D4:$M4,H$1)>0,$B4,0) -> 0 | I4: =IF(COUNTIF(Roster!$D4:$M4,I$1)>0,$B4,0) -> 1 | J4: =IF(COUNTIF(Roster!$D4:$M4,J$1)>0,$B4,0) -> 0 | ... W4: =IF(COUNTIF(Roster!$D4:$M4,W$1)>0,$B4,0) -> 0 | X4: =SUM(H4:W4) -> 4
A5: =Roster!A5 -> 4 | B5: =Roster!C5 -> 1 | C5: =IF(COUNTIF(Roster!$D5:$M5,C$1)>0,$B5,0) -> 1 | D5: =IF(COUNTIF(Roster!$D5:$M5,D$1)>0,$B5,0) -> 1 | E5: =IF(COUNTIF(Roster!$D5:$M5,E$1)>0,$B5,0) -> 1 | F5: =IF(COUNTIF(Roster!$D5:$M5,F$1)>0,$B5,0) -> 1 | G5: =IF(COUNTIF(Roster!$D5:$M5,G$1)>0,$B5,0) -> 0 | H5: =IF(COUNTIF(Roster!$D5:$M5,H$1)>0,$B5,0) -> 0 | I5: =IF(COUNTIF(Roster!$D5:$M5,I$1)>0,$B5,0) -> 1 | J5: =IF(COUNTIF(Roster!$D5:$M5,J$1)>0,$B5,0) -> 0 | ... W5: =IF(COUNTIF(Roster!$D5:$M5,W$1)>0,$B5,0) -> 0 | X5: =SUM(H5:W5) -> 4
A6: =Roster!A6 -> 5 | B6: =Roster!C6 -> 1 | C6: =IF(COUNTIF(Roster!$D6:$M6,C$1)>0,$B6,0) -> 1 | D6: =IF(COUNTIF(Roster!$D6:$M6,D$1)>0,$B6,0) -> 1 | E6: =IF(COUNTIF(Roster!$D6:$M6,E$1)>0,$B6,0) -> 1 | F6: =IF(COUNTIF(Roster!$D6:$M6,F$1)>0,$B6,0) -> 1 | G6: =IF(COUNTIF(Roster!$D6:$M6,G$1)>0,$B6,0) -> 0 | H6: =IF(COUNTIF(Roster!$D6:$M6,H$1)>0,$B6,0) -> 0 | I6: =IF(COUNTIF(Roster!$D6:$M6,I$1)>0,$B6,0) -> 1 | J6: =IF(COUNTIF(Roster!$D6:$M6,J$1)>0,$B6,0) -> 0 | ... W6: =IF(COUNTIF(Roster!$D6:$M6,W$1)>0,$B6,0) -> 0 | X6: =SUM(H6:W6) -> 4
A7: =Roster!A7 -> 6 | B7: =Roster!C7 -> 1 | C7: =IF(COUNTIF(Roster!$D7:$M7,C$1)>0,$B7,0) -> 1 | D7: =IF(COUNTIF(Roster!$D7:$M7,D$1)>0,$B7,0) -> 1 | E7: =IF(COUNTIF(Roster!$D7:$M7,E$1)>0,$B7,0) -> 1 | F7: =IF(COUNTIF(Roster!$D7:$M7,F$1)>0,$B7,0) -> 1 | G7: =IF(COUNTIF(Roster!$D7:$M7,G$1)>0,$B7,0) -> 0 | H7: =IF(COUNTIF(Roster!$D7:$M7,H$1)>0,$B7,0) -> 1 | I7: =IF(COUNTIF(Roster!$D7:$M7,I$1)>0,$B7,0) -> 1 | J7: =IF(COUNTIF(Roster!$D7:$M7,J$1)>0,$B7,0) -> 0 | ... W7: =IF(COUNTIF(Roster!$D7:$M7,W$1)>0,$B7,0) -> 0 | X7: =SUM(H7:W7) -> 5
A8: =Roster!A8 -> 7 | B8: =Roster!C8 -> 1 | C8: =IF(COUNTIF(Roster!$D8:$M8,C$1)>0,$B8,0) -> 1 | D8: =IF(COUNTIF(Roster!$D8:$M8,D$1)>0,$B8,0) -> 1 | E8: =IF(COUNTIF(Roster!$D8:$M8,E$1)>0,$B8,0) -> 1 | F8: =IF(COUNTIF(Roster!$D8:$M8,F$1)>0,$B8,0) -> 1 | G8: =IF(COUNTIF(Roster!$D8:$M8,G$1)>0,$B8,0) -> 0 | H8: =IF(COUNTIF(Roster!$D8:$M8,H$1)>0,$B8,0) -> 0 | I8: =IF(COUNTIF(Roster!$D8:$M8,I$1)>0,$B8,0) -> 1 | J8: =IF(COUNTIF(Roster!$D8:$M8,J$1)>0,$B8,0) -> 0 | ... W8: =IF(COUNTIF(Roster!$D8:$M8,W$1)>0,$B8,0) -> 0 | X8: =SUM(H8:W8) -> 4
A9: =Roster!A9 -> 8 | B9: =Roster!C9 -> 1 | C9: =IF(COUNTIF(Roster!$D9:$M9,C$1)>0,$B9,0) -> 1 | D9: =IF(COUNTIF(Roster!$D9:$M9,D$1)>0,$B9,0) -> 1 | E9: =IF(COUNTIF(Roster!$D9:$M9,E$1)>0,$B9,0) -> 1 | F9: =IF(COUNTIF(Roster!$D9:$M9,F$1)>0,$B9,0) -> 1 | G9: =IF(COUNTIF(Roster!$D9:$M9,G$1)>0,$B9,0) -> 0 | H9: =IF(COUNTIF(Roster!$D9:$M9,H$1)>0,$B9,0) -> 0 | I9: =IF(COUNTIF(Roster!$D9:$M9,I$1)>0,$B9,0) -> 1 | J9: =IF(COUNTIF(Roster!$D9:$M9,J$1)>0,$B9,0) -> 0 | ... W9: =IF(COUNTIF(Roster!$D9:$M9,W$1)>0,$B9,0) -> 0 | X9: =SUM(H9:W9) -> 4
A10: =Roster!A10 -> 9 | B10: =Roster!C10 -> 1 | C10: =IF(COUNTIF(Roster!$D10:$M10,C$1)>0,$B10,0) -> 1 | D10: =IF(COUNTIF(Roster!$D10:$M10,D$1)>0,$B10,0) -> 1 | E10: =IF(COUNTIF(Roster!$D10:$M10,E$1)>0,$B10,0) -> 1 | F10: =IF(COUNTIF(Roster!$D10:$M10,F$1)>0,$B10,0) -> 0 | G10: =IF(COUNTIF(Roster!$D10:$M10,G$1)>0,$B10,0) -> 1 | H10: =IF(COUNTIF(Roster!$D10:$M10,H$1)>0,$B10,0) -> 0 | I10: =IF(COUNTIF(Roster!$D10:$M10,I$1)>0,$B10,0) -> 1 | J10: =IF(COUNTIF(Roster!$D10:$M10,J$1)>0,$B10,0) -> 1 | ... W10: =IF(COUNTIF(Roster!$D10:$M10,W$1)>0,$B10,0) -> 0 | X10: =SUM(H10:W10) -> 4
A11: =Roster!A11 -> 10 | B11: =Roster!C11 -> 1 | C11: =IF(COUNTIF(Roster!$D11:$M11,C$1)>0,$B11,0) -> 1 | D11: =IF(COUNTIF(Roster!$D11:$M11,D$1)>0,$B11,0) -> 1 | E11: =IF(COUNTIF(Roster!$D11:$M11,E$1)>0,$B11,0) -> 1 | F11: =IF(COUNTIF(Roster!$D11:$M11,F$1)>0,$B11,0) -> 1 | G11: =IF(COUNTIF(Roster!$D11:$M11,G$1)>0,$B11,0) -> 0 | H11: =IF(COUNTIF(Roster!$D11:$M11,H$1)>0,$B11,0) -> 0 | I11: =IF(COUNTIF(Roster!$D11:$M11,I$1)>0,$B11,0) -> 1 | J11: =IF(COUNTIF(Roster!$D11:$M11,J$1)>0,$B11,0) -> 0 | ... W11: =IF(COUNTIF(Roster!$D11:$M11,W$1)>0,$B11,0) -> 0 | X11: =SUM(H11:W11) -> 4
A12: =Roster!A12 -> 11 | B12: =Roster!C12 -> 1 | C12: =IF(COUNTIF(Roster!$D12:$M12,C$1)>0,$B12,0) -> 1 | D12: =IF(COUNTIF(Roster!$D12:$M12,D$1)>0,$B12,0) -> 1 | E12: =IF(COUNTIF(Roster!$D12:$M12,E$1)>0,$B12,0) -> 1 | F12: =IF(COUNTIF(Roster!$D12:$M12,F$1)>0,$B12,0) -> 0 | G12: =IF(COUNTIF(Roster!$D12:$M12,G$1)>0,$B12,0) -> 1 | H12: =IF(COUNTIF(Roster!$D12:$M12,H$1)>0,$B12,0) -> 0 | I12: =IF(COUNTIF(Roster!$D12:$M12,I$1)>0,$B12,0) -> 1 | J12: =IF(COUNTIF(Roster!$D12:$M12,J$1)>0,$B12,0) -> 1 | ... W12: =IF(COUNTIF(Roster!$D12:$M12,W$1)>0,$B12,0) -> 0 | X12: =SUM(H12:W12) -> 4
A13: =Roster!A13 -> 12 | B13: =Roster!C13 -> 1 | C13: =IF(COUNTIF(Roster!$D13:$M13,C$1)>0,$B13,0) -> 1 | D13: =IF(COUNTIF(Roster!$D13:$M13,D$1)>0,$B13,0) -> 1 | E13: =IF(COUNTIF(Roster!$D13:$M13,E$1)>0,$B13,0) -> 1 | F13: =IF(COUNTIF(Roster!$D13:$M13,F$1)>0,$B13,0) -> 1 | G13: =IF(COUNTIF(Roster!$D13:$M13,G$1)>0,$B13,0) -> 0 | H13: =IF(COUNTIF(Roster!$D13:$M13,H$1)>0,$B13,0) -> 0 | I13: =IF(COUNTIF(Roster!$D13:$M13,I$1)>0,$B13,0) -> 1 | J13: =IF(COUNTIF(Roster!$D13:$M13,J$1)>0,$B13,0) -> 0 | ... W13: =IF(COUNTIF(Roster!$D13:$M13,W$1)>0,$B13,0) -> 0 | X13: =SUM(H13:W13) -> 4
... A267: =Roster!A267 -> 0 | B267: =Roster!C267 -> 0 | C267: =IF(COUNTIF(Roster!$D267:$M267,C$1)>0,$B267,0) -> 0 | D267: =IF(COUNTIF(Roster!$D267:$M267,D$1)>0,$B267,0) -> 0 | E267: =IF(COUNTIF(Roster!$D267:$M267,E$1)>0,$B267,0) -> 0 | F267: =IF(COUNTIF(Roster!$D267:$M267,F$1)>0,$B267,0) -> 0 | G267: =IF(COUNTIF(Roster!$D267:$M267,G$1)>0,$B267,0) -> 0 | H267: =IF(COUNTIF(Roster!$D267:$M267,H$1)>0,$B267,0) -> 0 | I267: =IF(COUNTIF(Roster!$D267:$M267,I$1)>0,$B267,0) -> 0 | J267: =IF(COUNTIF(Roster!$D267:$M267,J$1)>0,$B267,0) -> 0 | ... W267: =IF(COUNTIF(Roster!$D267:$M267,W$1)>0,$B267,0) -> 0 | X267: =SUM(H267:W267) -> 0

Sheet Subjects
A1: Phase 0 / Phase 1 — per-subject screen
A3: Subject | B3: Type | C3: Students | D3: Cap | E3: Section floor | F3: Pool size | G3: 2025 actual sections | H3: Status
A4: EN | B4: Universal | C4: =SUM(Matrix!C$2:C$267) -> 98 | D4: =Config!$B$3 -> 25 | E4: =IF(C4=0,0,ROUNDUP(C4/D4,0)) -> 4 | F4: 4 | G4: 6 | H4: =IF(C4=0,"not offered this grade",IF(F4=0,"NO QUALIFIED STAFF",IF(E4>F4,"OK - "&E4&" sections on "&F4&" staff; must sit in different columns","OK - pool covers floor"))) -> OK - pool covers floor
A5: LO | B5: Universal | C5: =SUM(Matrix!D$2:D$267) -> 98 | D5: =Config!$B$3 -> 25 | E5: =IF(C5=0,0,ROUNDUP(C5/D5,0)) -> 4 | F5: 2 | G5: 5 | H5: =IF(C5=0,"not offered this grade",IF(F5=0,"NO QUALIFIED STAFF",IF(E5>F5,"OK - "&E5&" sections on "&F5&" staff; must sit in different columns","OK - pool covers floor"))) -> OK - 4 sections on 2 staff; must sit in different columns
A6: PE | B6: Universal | C6: =SUM(Matrix!E$2:E$267) -> 98 | D6: =Config!$B$3 -> 25 | E6: =IF(C6=0,0,ROUNDUP(C6/D6,0)) -> 4 | F6: 3 | G6: 6 | H6: =IF(C6=0,"not offered this grade",IF(F6=0,"NO QUALIFIED STAFF",IF(E6>F6,"OK - "&E6&" sections on "&F6&" staff; must sit in different columns","OK - pool covers floor"))) -> OK - 4 sections on 3 staff; must sit in different columns
A7: MA | B7: Universal | C7: =SUM(Matrix!F$2:F$267) -> 66 | D7: =Config!$B$3 -> 25 | E7: =IF(C7=0,0,ROUNDUP(C7/D7,0)) -> 3 | F7: 3 | G7: 3 | H7: =IF(C7=0,"not offered this grade",IF(F7=0,"NO QUALIFIED STAFF",IF(E7>F7,"OK - "&E7&" sections on "&F7&" staff; must sit in different columns","OK - pool covers floor"))) -> OK - pool covers floor
A8: ML | B8: Universal | C8: =SUM(Matrix!G$2:G$267) -> 33 | D8: =Config!$B$3 -> 25 | E8: =IF(C8=0,0,ROUNDUP(C8/D8,0)) -> 2 | F8: 2 | G8: 2 | H8: =IF(C8=0,"not offered this grade",IF(F8=0,"NO QUALIFIED STAFF",IF(E8>F8,"OK - "&E8&" sections on "&F8&" staff; must sit in different columns","OK - pool covers floor"))) -> OK - pool covers floor
A9: AC | B9: Choice | C9: =SUM(Matrix!H$2:H$267) -> 22 | D9: =Config!$B$3 -> 25 | E9: =IF(C9=0,0,ROUNDUP(C9/D9,0)) -> 1 | F9: 1 | G9: 1 | H9: =IF(C9=0,"not offered this grade",IF(F9=0,"NO QUALIFIED STAFF",IF(E9>F9,"OK - "&E9&" sections on "&F9&" staff; must sit in different columns","OK - pool covers floor"))) -> OK - pool covers floor
A10: AF | B10: Choice | C10: =SUM(Matrix!I$2:I$267) -> 79 | D10: =Config!$B$3 -> 25 | E10: =IF(C10=0,0,ROUNDUP(C10/D10,0)) -> 4 | F10: 4 | G10: 4 | H10: =IF(C10=0,"not offered this grade",IF(F10=0,"NO QUALIFIED STAFF",IF(E10>F10,"OK - "&E10&" sections on "&F10&" staff; must sit in different columns","OK - pool covers floor"))) -> OK - pool covers floor
A11: BS | B11: Choice | C11: =SUM(Matrix!J$2:J$267) -> 55 | D11: =Config!$B$3 -> 25 | E11: =IF(C11=0,0,ROUNDUP(C11/D11,0)) -> 3 | F11: 1 | G11: 3 | H11: =IF(C11=0,"not offered this grade",IF(F11=0,"NO QUALIFIED STAFF",IF(E11>F11,"OK - "&E11&" sections on "&F11&" staff; must sit in different columns","OK - pool covers floor"))) -> OK - 3 sections on 1 staff; must sit in different columns
A12: CAT | B12: Choice | C12: =SUM(Matrix!K$2:K$267) -> 21 | D12: =Config!$B$3 -> 25 | E12: =IF(C12=0,0,ROUNDUP(C12/D12,0)) -> 1 | F12: 1 | G12: 1 | H12: =IF(C12=0,"not offered this grade",IF(F12=0,"NO QUALIFIED STAFF",IF(E12>F12,"OK - "&E12&" sections on "&F12&" staff; must sit in different columns","OK - pool covers floor"))) -> OK - pool covers floor
A13: DA | B13: Choice | C13: =SUM(Matrix!L$2:L$267) -> 16 | D13: =Config!$B$3 -> 25 | E13: =IF(C13=0,0,ROUNDUP(C13/D13,0)) -> 1 | F13: 1 | G13: 2 | H13: =IF(C13=0,"not offered this grade",IF(F13=0,"NO QUALIFIED STAFF",IF(E13>F13,"OK - "&E13&" sections on "&F13&" staff; must sit in different columns","OK - pool covers floor"))) -> OK - pool covers floor
A14: DR | B14: Choice | C14: =SUM(Matrix!M$2:M$267) -> 22 | D14: =Config!$B$3 -> 25 | E14: =IF(C14=0,0,ROUNDUP(C14/D14,0)) -> 1 | F14: 1 | G14: 2 | H14: =IF(C14=0,"not offered this grade",IF(F14=0,"NO QUALIFIED STAFF",IF(E14>F14,"OK - "&E14&" sections on "&F14&" staff; must sit in different columns","OK - pool covers floor"))) -> OK - pool covers floor
A15: ED | B15: Choice | C15: =SUM(Matrix!N$2:N$267) -> 17 | D15: =Config!$B$3 -> 25 | E15: =IF(C15=0,0,ROUNDUP(C15/D15,0)) -> 1 | F15: 1 | G15: 1 | H15: =IF(C15=0,"not offered this grade",IF(F15=0,"NO QUALIFIED STAFF",IF(E15>F15,"OK - "&E15&" sections on "&F15&" staff; must sit in different columns","OK - pool covers floor"))) -> OK - pool covers floor
A16: FR | B16: Choice | C16: =SUM(Matrix!O$2:O$267) -> 2 | D16: =Config!$B$3 -> 25 | E16: =IF(C16=0,0,ROUNDUP(C16/D16,0)) -> 1 | F16: 1 | G16: 1 | H16: =IF(C16=0,"not offered this grade",IF(F16=0,"NO QUALIFIED STAFF",IF(E16>F16,"OK - "&E16&" sections on "&F16&" staff; must sit in different columns","OK - pool covers floor"))) -> OK - pool covers floor
A17: GE | B17: Choice | C17: =SUM(Matrix!P$2:P$267) -> 14 | D17: =Config!$B$3 -> 25 | E17: =IF(C17=0,0,ROUNDUP(C17/D17,0)) -> 1 | F17: 1 | G17: 1 | H17: =IF(C17=0,"not offered this grade",IF(F17=0,"NO QUALIFIED STAFF",IF(E17>F17,"OK - "&E17&" sections on "&F17&" staff; must sit in different columns","OK - pool covers floor"))) -> OK - pool covers floor
A18: HI | B18: Choice | C18: =SUM(Matrix!Q$2:Q$267) -> 15 | D18: =Config!$B$3 -> 25 | E18: =IF(C18=0,0,ROUNDUP(C18/D18,0)) -> 1 | F18: 1 | G18: 1 | H18: =IF(C18=0,"not offered this grade",IF(F18=0,"NO QUALIFIED STAFF",IF(E18>F18,"OK - "&E18&" sections on "&F18&" staff; must sit in different columns","OK - pool covers floor"))) -> OK - pool covers floor
A19: IT | B19: Choice | C19: =SUM(Matrix!R$2:R$267) -> 11 | D19: =Config!$B$3 -> 25 | E19: =IF(C19=0,0,ROUNDUP(C19/D19,0)) -> 1 | F19: 1 | G19: 1 | H19: =IF(C19=0,"not offered this grade",IF(F19=0,"NO QUALIFIED STAFF",IF(E19>F19,"OK - "&E19&" sections on "&F19&" staff; must sit in different columns","OK - pool covers floor"))) -> OK - pool covers floor
A20: LS | B20: Choice | C20: =SUM(Matrix!S$2:S$267) -> 42 | D20: =Config!$B$3 -> 25 | E20: =IF(C20=0,0,ROUNDUP(C20/D20,0)) -> 2 | F20: 2 | G20: 2 | H20: =IF(C20=0,"not offered this grade",IF(F20=0,"NO QUALIFIED STAFF",IF(E20>F20,"OK - "&E20&" sections on "&F20&" staff; must sit in different columns","OK - pool covers floor"))) -> OK - pool covers floor
A21: MU | B21: Choice | C21: =SUM(Matrix!T$2:T$267) -> 4 | D21: =Config!$B$3 -> 25 | E21: =IF(C21=0,0,ROUNDUP(C21/D21,0)) -> 1 | F21: 1 | G21: 1 | H21: =IF(C21=0,"not offered this grade",IF(F21=0,"NO QUALIFIED STAFF",IF(E21>F21,"OK - "&E21&" sections on "&F21&" staff; must sit in different columns","OK - pool covers floor"))) -> OK - pool covers floor
A22: SC | B22: Choice | C22: =SUM(Matrix!U$2:U$267) -> 53 | D22: =Config!$B$3 -> 25 | E22: =IF(C22=0,0,ROUNDUP(C22/D22,0)) -> 3 | F22: 2 | G22: 4 | H22: =IF(C22=0,"not offered this grade",IF(F22=0,"NO QUALIFIED STAFF",IF(E22>F22,"OK - "&E22&" sections on "&F22&" staff; must sit in different columns","OK - pool covers floor"))) -> OK - 3 sections on 2 staff; must sit in different columns
A23: VA | B23: Choice | C23: =SUM(Matrix!V$2:V$267) -> 21 | D23: =Config!$B$3 -> 25 | E23: =IF(C23=0,0,ROUNDUP(C23/D23,0)) -> 1 | F23: 1 | G23: 2 | H23: =IF(C23=0,"not offered this grade",IF(F23=0,"NO QUALIFIED STAFF",IF(E23>F23,"OK - "&E23&" sections on "&F23&" staff; must sit in different columns","OK - pool covers floor"))) -> OK - pool covers floor
A24: ZU | B24: Choice | C24: =SUM(Matrix!W$2:W$267) -> 16 | D24: =Config!$B$3 -> 25 | E24: =IF(C24=0,0,ROUNDUP(C24/D24,0)) -> 1 | F24: 1 | G24: 1 | H24: =IF(C24=0,"not offered this grade",IF(F24=0,"NO QUALIFIED STAFF",IF(E24>F24,"OK - "&E24&" sections on "&F24&" staff; must sit in different columns","OK - pool covers floor"))) -> OK - pool covers floor
A26: Choice sections (floor) | E26: =SUM(E9:E24) -> 24
A27: Note | B27: Pool size limits sections running in the SAME column, not total sections. One teacher may cover several sections of a subject in different columns.
B28: Pool and 2025-actual columns are pre-filled from Teachers2025.xlsx for Grade 12. Re-enter them when analysing a different grade or school.

Sheet Conflict
A1: Phase 1 — choice-subject co-occurrence (students taking BOTH)
A2: Non-zero off-diagonal = the two subjects clash and cannot share a column when each has a single section. Diagonal = enrolment.
B4: AC | C4: AF | D4: BS | E4: CAT | F4: DA | G4: DR | H4: ED | I4: FR | J4: GE | K4: HI | L4: IT | M4: LS | N4: MU | O4: SC | P4: VA | Q4: ZU
A5: AC | B5: =SUMPRODUCT(INDEX(Matrix!$H$2:$W$267,0,ROW()-4),INDEX(Matrix!$H$2:$W$267,0,COLUMN()-1)) -> 22 | C5: =SUMPRODUCT(INDEX(Matrix!$H$2:$W$267,0,ROW()-4),INDEX(Matrix!$H$2:$W$267,0,COLUMN()-1)) -> 21 | D5: =SUMPRODUCT(INDEX(Matrix!$H$2:$W$267,0,ROW()-4),INDEX(Matrix!$H$2:$W$267,0,COLUMN()-1)) -> 11 | E5: =SUMPRODUCT(INDEX(Matrix!$H$2:$W$267,0,ROW()-4),INDEX(Matrix!$H$2:$W$267,0,COLUMN()-1)) -> 5 | F5: =SUMPRODUCT(INDEX(Matrix!$H$2:$W$267,0,ROW()-4),INDEX(Matrix!$H$2:$W$267,0,COLUMN()-1)) -> 1 | G5: =SUMPRODUCT(INDEX(Matrix!$H$2:$W$267,0,ROW()-4),INDEX(Matrix!$H$2:$W$267,0,COLUMN()-1)) -> 3 | H5: =SUMPRODUCT(INDEX(Matrix!$H$2:$W$267,0,ROW()-4),INDEX(Matrix!$H$2:$W$267,0,COLUMN()-1)) -> 2 | I5: =SUMPRODUCT(INDEX(Matrix!$H$2:$W$267,0,ROW()-4),INDEX(Matrix!$H$2:$W$267,0,COLUMN()-1)) -> 0 | ... Q5: =SUMPRODUCT(INDEX(Matrix!$H$2:$W$267,0,ROW()-4),INDEX(Matrix!$H$2:$W$267,0,COLUMN()-1)) -> 1
A6: AF | B6: =SUMPRODUCT(INDEX(Matrix!$H$2:$W$267,0,ROW()-4),INDEX(Matrix!$H$2:$W$267,0,COLUMN()-1)) -> 21 | C6: =SUMPRODUCT(INDEX(Matrix!$H$2:$W$267,0,ROW()-4),INDEX(Matrix!$H$2:$W$267,0,COLUMN()-1)) -> 79 | D6: =SUMPRODUCT(INDEX(Matrix!$H$2:$W$267,0,ROW()-4),INDEX(Matrix!$H$2:$W$267,0,COLUMN()-1)) -> 43 | E6: =SUMPRODUCT(INDEX(Matrix!$H$2:$W$267,0,ROW()-4),INDEX(Matrix!$H$2:$W$267,0,COLUMN()-1)) -> 19 | F6: =SUMPRODUCT(INDEX(Matrix!$H$2:$W$267,0,ROW()-4),INDEX(Matrix!$H$2:$W$267,0,COLUMN()-1)) -> 11 | G6: =SUMPRODUCT(INDEX(Matrix!$H$2:$W$267,0,ROW()-4),INDEX(Matrix!$H$2:$W$267,0,COLUMN()-1)) -> 14 | H6: =SUMPRODUCT(INDEX(Matrix!$H$2:$W$267,0,ROW()-4),INDEX(Matrix!$H$2:$W$267,0,COLUMN()-1)) -> 15 | I6: =SUMPRODUCT(INDEX(Matrix!$H$2:$W$267,0,ROW()-4),INDEX(Matrix!$H$2:$W$267,0,COLUMN()-1)) -> 0 | ... Q6: =SUMPRODUCT(INDEX(Matrix!$H$2:$W$267,0,ROW()-4),INDEX(Matrix!$H$2:$W$267,0,COLUMN()-1)) -> 0
A7: BS | B7: =SUMPRODUCT(INDEX(Matrix!$H$2:$W$267,0,ROW()-4),INDEX(Matrix!$H$2:$W$267,0,COLUMN()-1)) -> 11 | C7: =SUMPRODUCT(INDEX(Matrix!$H$2:$W$267,0,ROW()-4),INDEX(Matrix!$H$2:$W$267,0,COLUMN()-1)) -> 43 | D7: =SUMPRODUCT(INDEX(Matrix!$H$2:$W$267,0,ROW()-4),INDEX(Matrix!$H$2:$W$267,0,COLUMN()-1)) -> 55 | E7: =SUMPRODUCT(INDEX(Matrix!$H$2:$W$267,0,ROW()-4),INDEX(Matrix!$H$2:$W$267,0,COLUMN()-1)) -> 12 | F7: =SUMPRODUCT(INDEX(Matrix!$H$2:$W$267,0,ROW()-4),INDEX(Matrix!$H$2:$W$267,0,COLUMN()-1)) -> 14 | G7: =SUMPRODUCT(INDEX(Matrix!$H$2:$W$267,0,ROW()-4),INDEX(Matrix!$H$2:$W$267,0,COLUMN()-1)) -> 14 | H7: =SUMPRODUCT(INDEX(Matrix!$H$2:$W$267,0,ROW()-4),INDEX(Matrix!$H$2:$W$267,0,COLUMN()-1)) -> 4 | I7: =SUMPRODUCT(INDEX(Matrix!$H$2:$W$267,0,ROW()-4),INDEX(Matrix!$H$2:$W$267,0,COLUMN()-1)) -> 0 | ... Q7: =SUMPRODUCT(INDEX(Matrix!$H$2:$W$267,0,ROW()-4),INDEX(Matrix!$H$2:$W$267,0,COLUMN()-1)) -> 10
A8: CAT | B8: =SUMPRODUCT(INDEX(Matrix!$H$2:$W$267,0,ROW()-4),INDEX(Matrix!$H$2:$W$267,0,COLUMN()-1)) -> 5 | C8: =SUMPRODUCT(INDEX(Matrix!$H$2:$W$267,0,ROW()-4),INDEX(Matrix!$H$2:$W$267,0,COLUMN()-1)) -> 19 | D8: =SUMPRODUCT(INDEX(Matrix!$H$2:$W$267,0,ROW()-4),INDEX(Matrix!$H$2:$W$267,0,COLUMN()-1)) -> 12 | E8: =SUMPRODUCT(INDEX(Matrix!$H$2:$W$267,0,ROW()-4),INDEX(Matrix!$H$2:$W$267,0,COLUMN()-1)) -> 21 | F8: =SUMPRODUCT(INDEX(Matrix!$H$2:$W$267,0,ROW()-4),INDEX(Matrix!$H$2:$W$267,0,COLUMN()-1)) -> 2 | G8: =SUMPRODUCT(INDEX(Matrix!$H$2:$W$267,0,ROW()-4),INDEX(Matrix!$H$2:$W$267,0,COLUMN()-1)) -> 1 | H8: =SUMPRODUCT(INDEX(Matrix!$H$2:$W$267,0,ROW()-4),INDEX(Matrix!$H$2:$W$267,0,COLUMN()-1)) -> 2 | I8: =SUMPRODUCT(INDEX(Matrix!$H$2:$W$267,0,ROW()-4),INDEX(Matrix!$H$2:$W$267,0,COLUMN()-1)) -> 0 | ... Q8: =SUMPRODUCT(INDEX(Matrix!$H$2:$W$267,0,ROW()-4),INDEX(Matrix!$H$2:$W$267,0,COLUMN()-1)) -> 2
A9: DA | B9: =SUMPRODUCT(INDEX(Matrix!$H$2:$W$267,0,ROW()-4),INDEX(Matrix!$H$2:$W$267,0,COLUMN()-1)) -> 1 | C9: =SUMPRODUCT(INDEX(Matrix!$H$2:$W$267,0,ROW()-4),INDEX(Matrix!$H$2:$W$267,0,COLUMN()-1)) -> 11 | D9: =SUMPRODUCT(INDEX(Matrix!$H$2:$W$267,0,ROW()-4),INDEX(Matrix!$H$2:$W$267,0,COLUMN()-1)) -> 14 | E9: =SUMPRODUCT(INDEX(Matrix!$H$2:$W$267,0,ROW()-4),INDEX(Matrix!$H$2:$W$267,0,COLUMN()-1)) -> 2 | F9: =SUMPRODUCT(INDEX(Matrix!$H$2:$W$267,0,ROW()-4),INDEX(Matrix!$H$2:$W$267,0,COLUMN()-1)) -> 16 | G9: =SUMPRODUCT(INDEX(Matrix!$H$2:$W$267,0,ROW()-4),INDEX(Matrix!$H$2:$W$267,0,COLUMN()-1)) -> 4 | H9: =SUMPRODUCT(INDEX(Matrix!$H$2:$W$267,0,ROW()-4),INDEX(Matrix!$H$2:$W$267,0,COLUMN()-1)) -> 0 | I9: =SUMPRODUCT(INDEX(Matrix!$H$2:$W$267,0,ROW()-4),INDEX(Matrix!$H$2:$W$267,0,COLUMN()-1)) -> 0 | ... Q9: =SUMPRODUCT(INDEX(Matrix!$H$2:$W$267,0,ROW()-4),INDEX(Matrix!$H$2:$W$267,0,COLUMN()-1)) -> 5
A10: DR | B10: =SUMPRODUCT(INDEX(Matrix!$H$2:$W$267,0,ROW()-4),INDEX(Matrix!$H$2:$W$267,0,COLUMN()-1)) -> 3 | C10: =SUMPRODUCT(INDEX(Matrix!$H$2:$W$267,0,ROW()-4),INDEX(Matrix!$H$2:$W$267,0,COLUMN()-1)) -> 14 | D10: =SUMPRODUCT(INDEX(Matrix!$H$2:$W$267,0,ROW()-4),INDEX(Matrix!$H$2:$W$267,0,COLUMN()-1)) -> 14 | E10: =SUMPRODUCT(INDEX(Matrix!$H$2:$W$267,0,ROW()-4),INDEX(Matrix!$H$2:$W$267,0,COLUMN()-1)) -> 1 | F10: =SUMPRODUCT(INDEX(Matrix!$H$2:$W$267,0,ROW()-4),INDEX(Matrix!$H$2:$W$267,0,COLUMN()-1)) -> 4 | G10: =SUMPRODUCT(INDEX(Matrix!$H$2:$W$267,0,ROW()-4),INDEX(Matrix!$H$2:$W$267,0,COLUMN()-1)) -> 22 | H10: =SUMPRODUCT(INDEX(Matrix!$H$2:$W$267,0,ROW()-4),INDEX(Matrix!$H$2:$W$267,0,COLUMN()-1)) -> 3 | I10: =SUMPRODUCT(INDEX(Matrix!$H$2:$W$267,0,ROW()-4),INDEX(Matrix!$H$2:$W$267,0,COLUMN()-1)) -> 0 | ... Q10: =SUMPRODUCT(INDEX(Matrix!$H$2:$W$267,0,ROW()-4),INDEX(Matrix!$H$2:$W$267,0,COLUMN()-1)) -> 7
A11: ED | B11: =SUMPRODUCT(INDEX(Matrix!$H$2:$W$267,0,ROW()-4),INDEX(Matrix!$H$2:$W$267,0,COLUMN()-1)) -> 2 | C11: =SUMPRODUCT(INDEX(Matrix!$H$2:$W$267,0,ROW()-4),INDEX(Matrix!$H$2:$W$267,0,COLUMN()-1)) -> 15 | D11: =SUMPRODUCT(INDEX(Matrix!$H$2:$W$267,0,ROW()-4),INDEX(Matrix!$H$2:$W$267,0,COLUMN()-1)) -> 4 | E11: =SUMPRODUCT(INDEX(Matrix!$H$2:$W$267,0,ROW()-4),INDEX(Matrix!$H$2:$W$267,0,COLUMN()-1)) -> 2 | F11: =SUMPRODUCT(INDEX(Matrix!$H$2:$W$267,0,ROW()-4),INDEX(Matrix!$H$2:$W$267,0,COLUMN()-1)) -> 0 | G11: =SUMPRODUCT(INDEX(Matrix!$H$2:$W$267,0,ROW()-4),INDEX(Matrix!$H$2:$W$267,0,COLUMN()-1)) -> 3 | H11: =SUMPRODUCT(INDEX(Matrix!$H$2:$W$267,0,ROW()-4),INDEX(Matrix!$H$2:$W$267,0,COLUMN()-1)) -> 17 | I11: =SUMPRODUCT(INDEX(Matrix!$H$2:$W$267,0,ROW()-4),INDEX(Matrix!$H$2:$W$267,0,COLUMN()-1)) -> 0 | ... Q11: =SUMPRODUCT(INDEX(Matrix!$H$2:$W$267,0,ROW()-4),INDEX(Matrix!$H$2:$W$267,0,COLUMN()-1)) -> 2
A12: FR | B12: =SUMPRODUCT(INDEX(Matrix!$H$2:$W$267,0,ROW()-4),INDEX(Matrix!$H$2:$W$267,0,COLUMN()-1)) -> 0 | C12: =SUMPRODUCT(INDEX(Matrix!$H$2:$W$267,0,ROW()-4),INDEX(Matrix!$H$2:$W$267,0,COLUMN()-1)) -> 0 | D12: =SUMPRODUCT(INDEX(Matrix!$H$2:$W$267,0,ROW()-4),INDEX(Matrix!$H$2:$W$267,0,COLUMN()-1)) -> 0 | E12: =SUMPRODUCT(INDEX(Matrix!$H$2:$W$267,0,ROW()-4),INDEX(Matrix!$H$2:$W$267,0,COLUMN()-1)) -> 0 | F12: =SUMPRODUCT(INDEX(Matrix!$H$2:$W$267,0,ROW()-4),INDEX(Matrix!$H$2:$W$267,0,COLUMN()-1)) -> 0 | G12: =SUMPRODUCT(INDEX(Matrix!$H$2:$W$267,0,ROW()-4),INDEX(Matrix!$H$2:$W$267,0,COLUMN()-1)) -> 0 | H12: =SUMPRODUCT(INDEX(Matrix!$H$2:$W$267,0,ROW()-4),INDEX(Matrix!$H$2:$W$267,0,COLUMN()-1)) -> 0 | I12: =SUMPRODUCT(INDEX(Matrix!$H$2:$W$267,0,ROW()-4),INDEX(Matrix!$H$2:$W$267,0,COLUMN()-1)) -> 2 | ... Q12: =SUMPRODUCT(INDEX(Matrix!$H$2:$W$267,0,ROW()-4),INDEX(Matrix!$H$2:$W$267,0,COLUMN()-1)) -> 1
A13: GE | B13: =SUMPRODUCT(INDEX(Matrix!$H$2:$W$267,0,ROW()-4),INDEX(Matrix!$H$2:$W$267,0,COLUMN()-1)) -> 1 | C13: =SUMPRODUCT(INDEX(Matrix!$H$2:$W$267,0,ROW()-4),INDEX(Matrix!$H$2:$W$267,0,COLUMN()-1)) -> 7 | D13: =SUMPRODUCT(INDEX(Matrix!$H$2:$W$267,0,ROW()-4),INDEX(Matrix!$H$2:$W$267,0,COLUMN()-1)) -> 9 | E13: =SUMPRODUCT(INDEX(Matrix!$H$2:$W$267,0,ROW()-4),INDEX(Matrix!$H$2:$W$267,0,COLUMN()-1)) -> 3 | F13: =SUMPRODUCT(INDEX(Matrix!$H$2:$W$267,0,ROW()-4),INDEX(Matrix!$H$2:$W$267,0,COLUMN()-1)) -> 1 | G13: =SUMPRODUCT(INDEX(Matrix!$H$2:$W$267,0,ROW()-4),INDEX(Matrix!$H$2:$W$267,0,COLUMN()-1)) -> 2 | H13: =SUMPRODUCT(INDEX(Matrix!$H$2:$W$267,0,ROW()-4),INDEX(Matrix!$H$2:$W$267,0,COLUMN()-1)) -> 0 | I13: =SUMPRODUCT(INDEX(Matrix!$H$2:$W$267,0,ROW()-4),INDEX(Matrix!$H$2:$W$267,0,COLUMN()-1)) -> 1 | ... Q13: =SUMPRODUCT(INDEX(Matrix!$H$2:$W$267,0,ROW()-4),INDEX(Matrix!$H$2:$W$267,0,COLUMN()-1)) -> 6
A14: HI | B14: =SUMPRODUCT(INDEX(Matrix!$H$2:$W$267,0,ROW()-4),INDEX(Matrix!$H$2:$W$267,0,COLUMN()-1)) -> 2 | C14: =SUMPRODUCT(INDEX(Matrix!$H$2:$W$267,0,ROW()-4),INDEX(Matrix!$H$2:$W$267,0,COLUMN()-1)) -> 12 | D14: =SUMPRODUCT(INDEX(Matrix!$H$2:$W$267,0,ROW()-4),INDEX(Matrix!$H$2:$W$267,0,COLUMN()-1)) -> 13 | E14: =SUMPRODUCT(INDEX(Matrix!$H$2:$W$267,0,ROW()-4),INDEX(Matrix!$H$2:$W$267,0,COLUMN()-1)) -> 1 | F14: =SUMPRODUCT(INDEX(Matrix!$H$2:$W$267,0,ROW()-4),INDEX(Matrix!$H$2:$W$267,0,COLUMN()-1)) -> 2 | G14: =SUMPRODUCT(INDEX(Matrix!$H$2:$W$267,0,ROW()-4),INDEX(Matrix!$H$2:$W$267,0,COLUMN()-1)) -> 4 | H14: =SUMPRODUCT(INDEX(Matrix!$H$2:$W$267,0,ROW()-4),INDEX(Matrix!$H$2:$W$267,0,COLUMN()-1)) -> 1 | I14: =SUMPRODUCT(INDEX(Matrix!$H$2:$W$267,0,ROW()-4),INDEX(Matrix!$H$2:$W$267,0,COLUMN()-1)) -> 0 | ... Q14: =SUMPRODUCT(INDEX(Matrix!$H$2:$W$267,0,ROW()-4),INDEX(Matrix!$H$2:$W$267,0,COLUMN()-1)) -> 2
A15: IT | B15: =SUMPRODUCT(INDEX(Matrix!$H$2:$W$267,0,ROW()-4),INDEX(Matrix!$H$2:$W$267,0,COLUMN()-1)) -> 2 | C15: =SUMPRODUCT(INDEX(Matrix!$H$2:$W$267,0,ROW()-4),INDEX(Matrix!$H$2:$W$267,0,COLUMN()-1)) -> 11 | D15: =SUMPRODUCT(INDEX(Matrix!$H$2:$W$267,0,ROW()-4),INDEX(Matrix!$H$2:$W$267,0,COLUMN()-1)) -> 0 | E15: =SUMPRODUCT(INDEX(Matrix!$H$2:$W$267,0,ROW()-4),INDEX(Matrix!$H$2:$W$267,0,COLUMN()-1)) -> 3 | F15: =SUMPRODUCT(INDEX(Matrix!$H$2:$W$267,0,ROW()-4),INDEX(Matrix!$H$2:$W$267,0,COLUMN()-1)) -> 0 | G15: =SUMPRODUCT(INDEX(Matrix!$H$2:$W$267,0,ROW()-4),INDEX(Matrix!$H$2:$W$267,0,COLUMN()-1)) -> 2 | H15: =SUMPRODUCT(INDEX(Matrix!$H$2:$W$267,0,ROW()-4),INDEX(Matrix!$H$2:$W$267,0,COLUMN()-1)) -> 4 | I15: =SUMPRODUCT(INDEX(Matrix!$H$2:$W$267,0,ROW()-4),INDEX(Matrix!$H$2:$W$267,0,COLUMN()-1)) -> 0 | ... Q15: =SUMPRODUCT(INDEX(Matrix!$H$2:$W$267,0,ROW()-4),INDEX(Matrix!$H$2:$W$267,0,COLUMN()-1)) -> 0
A16: LS | B16: =SUMPRODUCT(INDEX(Matrix!$H$2:$W$267,0,ROW()-4),INDEX(Matrix!$H$2:$W$267,0,COLUMN()-1)) -> 5 | C16: =SUMPRODUCT(INDEX(Matrix!$H$2:$W$267,0,ROW()-4),INDEX(Matrix!$H$2:$W$267,0,COLUMN()-1)) -> 33 | D16: =SUMPRODUCT(INDEX(Matrix!$H$2:$W$267,0,ROW()-4),INDEX(Matrix!$H$2:$W$267,0,COLUMN()-1)) -> 22 | E16: =SUMPRODUCT(INDEX(Matrix!$H$2:$W$267,0,ROW()-4),INDEX(Matrix!$H$2:$W$267,0,COLUMN()-1)) -> 4 | F16: =SUMPRODUCT(INDEX(Matrix!$H$2:$W$267,0,ROW()-4),INDEX(Matrix!$H$2:$W$267,0,COLUMN()-1)) -> 8 | G16: =SUMPRODUCT(INDEX(Matrix!$H$2:$W$267,0,ROW()-4),INDEX(Matrix!$H$2:$W$267,0,COLUMN()-1)) -> 6 | H16: =SUMPRODUCT(INDEX(Matrix!$H$2:$W$267,0,ROW()-4),INDEX(Matrix!$H$2:$W$267,0,COLUMN()-1)) -> 4 | I16: =SUMPRODUCT(INDEX(Matrix!$H$2:$W$267,0,ROW()-4),INDEX(Matrix!$H$2:$W$267,0,COLUMN()-1)) -> 2 | ... Q16: =SUMPRODUCT(INDEX(Matrix!$H$2:$W$267,0,ROW()-4),INDEX(Matrix!$H$2:$W$267,0,COLUMN()-1)) -> 6
... A20: ZU | B20: =SUMPRODUCT(INDEX(Matrix!$H$2:$W$267,0,ROW()-4),INDEX(Matrix!$H$2:$W$267,0,COLUMN()-1)) -> 1 | C20: =SUMPRODUCT(INDEX(Matrix!$H$2:$W$267,0,ROW()-4),INDEX(Matrix!$H$2:$W$267,0,COLUMN()-1)) -> 0 | D20: =SUMPRODUCT(INDEX(Matrix!$H$2:$W$267,0,ROW()-4),INDEX(Matrix!$H$2:$W$267,0,COLUMN()-1)) -> 10 | E20: =SUMPRODUCT(INDEX(Matrix!$H$2:$W$267,0,ROW()-4),INDEX(Matrix!$H$2:$W$267,0,COLUMN()-1)) -> 2 | F20: =SUMPRODUCT(INDEX(Matrix!$H$2:$W$267,0,ROW()-4),INDEX(Matrix!$H$2:$W$267,0,COLUMN()-1)) -> 5 | G20: =SUMPRODUCT(INDEX(Matrix!$H$2:$W$267,0,ROW()-4),INDEX(Matrix!$H$2:$W$267,0,COLUMN()-1)) -> 7 | H20: =SUMPRODUCT(INDEX(Matrix!$H$2:$W$267,0,ROW()-4),INDEX(Matrix!$H$2:$W$267,0,COLUMN()-1)) -> 2 | I20: =SUMPRODUCT(INDEX(Matrix!$H$2:$W$267,0,ROW()-4),INDEX(Matrix!$H$2:$W$267,0,COLUMN()-1)) -> 1 | ... Q20: =SUMPRODUCT(INDEX(Matrix!$H$2:$W$267,0,ROW()-4),INDEX(Matrix!$H$2:$W$267,0,COLUMN()-1)) -> 16
A21: Degree | B21: =COUNTIF(B5:B20,">0")-1 -> 14 | C21: =COUNTIF(C5:C20,">0")-1 -> 13 | D21: =COUNTIF(D5:D20,">0")-1 -> 12 | E21: =COUNTIF(E5:E20,">0")-1 -> 13 | F21: =COUNTIF(F5:F20,">0")-1 -> 10 | G21: =COUNTIF(G5:G20,">0")-1 -> 14 | H21: =COUNTIF(H5:H20,">0")-1 -> 12 | I21: =COUNTIF(I5:I20,">0")-1 -> 5 | ... Q21: =COUNTIF(Q5:Q20,">0")-1 -> 13
A22: Degree = number of other choice subjects this one clashes with.

Sheet Bounds
A1: Phase 1 - lower bounds on column count
A3: Grade analysed | B3: =Config!$B$2 -> 12 | C3: From Config.
A4: Students in scope | B4: =SUM(Matrix!$B$2:$B$267) -> 98 | C4: Roster rows matching the selected grade.
A5: Class-size cap | B5: =Config!$B$3 -> 25 | C5: From Config.
A7: BOUND 1 Max basket size | B7: =MAX(Matrix!X$2:X$267) -> 5 | C7: The largest number of choice subjects any single student takes. That student needs this many distinct columns. Hard floor - no amount of staffing beats it.
A8: BOUND 2 Max clique | B8: n/a | C8: Not computable in plain Excel. Bound 1 is itself a clique, so the true clique bound is always >= Bound 1. Compute in Phase 3 if Bound 1 passes.
A10: COLUMNS REQUIRED (lower bound) | B10: =B7 -> 5 | C10: The choice block cannot be built in fewer columns than this.
A12: Columns available | B12: 8 | C12: TYPE THIS. Total parallel columns in the school timetable shape.
A13: Columns used by universal block | B13: 3 | C13: TYPE THIS. E.g. EN takes 1 column, MA/ML/PE/LO share 2.
A14: Columns left for choice subjects | B14: =B12-B13 -> 5
A16: VERDICT | B16: =IF(B14<B10,"INFEASIBLE - needs "&B10&" columns, only "&B14&" free","Not yet proven infeasible - proceed to Phase 2") -> Not yet proven infeasible - proceed to Phase 2 | C16: A pass is a floor check only. Phase 3 (CP-SAT) is the arbiter of true feasibility.
A17: Students needing manual handling | B17: =COUNTIF(Matrix!X$2:X$267,">"&B14) -> 0 | C17: Baskets larger than the free block. Quarantine these as exceptions - do not size the grid around them.
A19: Choice sections at floor | B19: =Subjects!$E$26 -> 24 | C19: Sum of per-subject section floors. Lower bound on total choice classes to staff.
